<robot name="mycar">
    <link name="base_link">
        <visual>
            <geometry>
                <box size="0.3 0.2 0.1"/>
            </geometry>

            <origin xyz="0 0 0" rpy="0 0 0"/>

            <material name="car_color">
                <color rgba="0.3 0.2 0.8 0.6"/>
            </material>
        </visual>
    </link>


    <link name="camera">
        <visual>
            <geometry>
                <box size="0.02 0.05 0.05" />
            </geometry>

            <origin xyz="0 0 0" rpy="0 0 0" />

            <material name="red">
                <color rgba="0.1 0.8 0.1 0.6" />
            </material>
        </visual>
    </link>


    <joint name="camera2baselink" type="continuous">
        <parent link="base_link" />
        <child link="camera" />
        <origin xyz="0.2 0 0.075" rpy="0 0 0" />
        <axis xyz="0 0 1" />

    </joint>

</robot>